[2022-08-30 18:21:12,082] {taskinstance.py:1179} INFO - Dependencies all met for <TaskInstance: dynamically_branching1.query_table manual__2022-08-26T19:30:47.259727+00:00 [queued]>
[2022-08-30 18:21:12,247] {taskinstance.py:1179} INFO - Dependencies all met for <TaskInstance: dynamically_branching1.query_table manual__2022-08-26T19:30:47.259727+00:00 [queued]>
[2022-08-30 18:21:12,249] {taskinstance.py:1376} INFO - 
--------------------------------------------------------------------------------
[2022-08-30 18:21:12,251] {taskinstance.py:1377} INFO - Starting attempt 1 of 1
[2022-08-30 18:21:12,252] {taskinstance.py:1378} INFO - 
--------------------------------------------------------------------------------
[2022-08-30 18:21:12,356] {taskinstance.py:1397} INFO - Executing <Task(PythonOperator): query_table> on 2022-08-26 19:30:47.259727+00:00
[2022-08-30 18:21:12,412] {standard_task_runner.py:52} INFO - Started process 75752 to run task
[2022-08-30 18:21:12,463] {standard_task_runner.py:79} INFO - Running: ['***', 'tasks', 'run', 'dynamically_branching1', 'query_table', 'manual__2022-08-26T19:30:47.259727+00:00', '--job-id', '3358', '--raw', '--subdir', 'DAGS_FOLDER/jobs_dag.py', '--cfg-path', '/tmp/tmpmlmj8y86', '--error-file', '/tmp/tmp_rsevrni']
[2022-08-30 18:21:12,481] {standard_task_runner.py:80} INFO - Job 3358: Subtask query_table
[2022-08-30 18:21:13,068] {task_command.py:371} INFO - Running <TaskInstance: dynamically_branching1.query_table manual__2022-08-26T19:30:47.259727+00:00 [running]> on host 9d5d2a77e6ba
[2022-08-30 18:21:13,687] {taskinstance.py:1591} INFO - Exporting the following env vars:
AIRFLOW_CTX_DAG_OWNER=***
AIRFLOW_CTX_DAG_ID=dynamically_branching1
AIRFLOW_CTX_TASK_ID=query_table
AIRFLOW_CTX_EXECUTION_DATE=2022-08-26T19:30:47.259727+00:00
AIRFLOW_CTX_TRY_NUMBER=1
AIRFLOW_CTX_DAG_RUN_ID=manual__2022-08-26T19:30:47.259727+00:00
[2022-08-30 18:21:13,706] {taskinstance.py:1909} ERROR - Task failed with exception
Traceback (most recent call last):
  File "/home/airflow/.local/lib/python3.7/site-packages/airflow/operators/python.py", line 171, in execute
    return_value = self.execute_callable()
  File "/home/airflow/.local/lib/python3.7/site-packages/airflow/operators/python.py", line 189, in execute_callable
    return self.python_callable(*self.op_args, **self.op_kwargs)
  File "/opt/airflow/dags/jobs_dag.py", line 39, in xcom_call
    ti.xcom_push(key='ended_id',value={{'run_id'}})
TypeError: unhashable type: 'set'
[2022-08-30 18:21:13,859] {taskinstance.py:1420} INFO - Marking task as FAILED. dag_id=dynamically_branching1, task_id=query_table, execution_date=20220826T193047, start_date=20220830T182112, end_date=20220830T182113
[2022-08-30 18:21:14,059] {standard_task_runner.py:97} ERROR - Failed to execute job 3358 for task query_table (unhashable type: 'set'; 75752)
[2022-08-30 18:21:14,287] {local_task_job.py:156} INFO - Task exited with return code 1
[2022-08-30 18:21:14,920] {local_task_job.py:273} INFO - 0 downstream tasks scheduled from follow-on schedule check
