[2022-09-05 19:56:11,867] {taskinstance.py:1179} INFO - Dependencies all met for <TaskInstance: my_dag_postgres2.insert_into_table scheduled__2021-01-01T00:00:00+00:00 [queued]>
[2022-09-05 19:56:11,885] {taskinstance.py:1179} INFO - Dependencies all met for <TaskInstance: my_dag_postgres2.insert_into_table scheduled__2021-01-01T00:00:00+00:00 [queued]>
[2022-09-05 19:56:11,886] {taskinstance.py:1376} INFO - 
--------------------------------------------------------------------------------
[2022-09-05 19:56:11,886] {taskinstance.py:1377} INFO - Starting attempt 1 of 1
[2022-09-05 19:56:11,887] {taskinstance.py:1378} INFO - 
--------------------------------------------------------------------------------
[2022-09-05 19:56:11,926] {taskinstance.py:1397} INFO - Executing <Task(PostgresOperator): insert_into_table> on 2021-01-01 00:00:00+00:00
[2022-09-05 19:56:11,937] {standard_task_runner.py:52} INFO - Started process 2245 to run task
[2022-09-05 19:56:11,952] {standard_task_runner.py:79} INFO - Running: ['***', 'tasks', 'run', 'my_dag_postgres2', 'insert_into_table', 'scheduled__2021-01-01T00:00:00+00:00', '--job-id', '3822', '--raw', '--subdir', 'DAGS_FOLDER/dag_with_postgres.py', '--cfg-path', '/tmp/tmp18m61xrf', '--error-file', '/tmp/tmptd73kvja']
[2022-09-05 19:56:11,954] {standard_task_runner.py:80} INFO - Job 3822: Subtask insert_into_table
[2022-09-05 19:56:12,105] {task_command.py:371} INFO - Running <TaskInstance: my_dag_postgres2.insert_into_table scheduled__2021-01-01T00:00:00+00:00 [running]> on host eba23da77ca5
[2022-09-05 19:56:12,178] {taskinstance.py:1909} ERROR - Task failed with exception
Traceback (most recent call last):
  File "/home/airflow/.local/lib/python3.7/site-packages/airflow/models/taskinstance.py", line 1471, in _run_raw_task
    self._execute_task_with_callbacks(context, test_mode)
  File "/home/airflow/.local/lib/python3.7/site-packages/airflow/models/taskinstance.py", line 1575, in _execute_task_with_callbacks
    task_orig = self.render_templates(context=context)
  File "/home/airflow/.local/lib/python3.7/site-packages/airflow/models/taskinstance.py", line 2232, in render_templates
    rendered_task = self.task.render_template_fields(context)
  File "/home/airflow/.local/lib/python3.7/site-packages/airflow/models/baseoperator.py", line 1188, in render_template_fields
    self._do_render_template_fields(self, self.template_fields, context, jinja_env, set())
  File "/home/airflow/.local/lib/python3.7/site-packages/airflow/utils/session.py", line 71, in wrapper
    return func(*args, session=session, **kwargs)
  File "/home/airflow/.local/lib/python3.7/site-packages/airflow/models/abstractoperator.py", line 347, in _do_render_template_fields
    seen_oids,
  File "/home/airflow/.local/lib/python3.7/site-packages/airflow/models/abstractoperator.py", line 390, in render_template
    return render_template_to_string(template, context)
  File "/home/airflow/.local/lib/python3.7/site-packages/airflow/utils/helpers.py", line 296, in render_template_to_string
    return render_template(template, context, native=False)
  File "/home/airflow/.local/lib/python3.7/site-packages/airflow/utils/helpers.py", line 291, in render_template
    return "".join(nodes)
  File "<template>", line 14, in root
  File "/home/airflow/.local/lib/python3.7/site-packages/jinja2/runtime.py", line 852, in _fail_with_undefined_error
    raise self._undefined_exception(self._undefined_message)
jinja2.exceptions.UndefinedError: 'dt' is undefined
[2022-09-05 19:56:12,195] {taskinstance.py:1420} INFO - Marking task as FAILED. dag_id=my_dag_postgres2, task_id=insert_into_table, execution_date=20210101T000000, start_date=20220905T195611, end_date=20220905T195612
[2022-09-05 19:56:12,209] {standard_task_runner.py:97} ERROR - Failed to execute job 3822 for task insert_into_table ('dt' is undefined; 2245)
[2022-09-05 19:56:12,243] {local_task_job.py:156} INFO - Task exited with return code 1
[2022-09-05 19:56:12,288] {local_task_job.py:273} INFO - 0 downstream tasks scheduled from follow-on schedule check
