[2022-09-06 20:44:24,903] {taskinstance.py:1179} INFO - Dependencies all met for <TaskInstance: tables_name_1.create_table manual__2022-09-06T20:44:20.990231+00:00 [queued]>
[2022-09-06 20:44:24,919] {taskinstance.py:1179} INFO - Dependencies all met for <TaskInstance: tables_name_1.create_table manual__2022-09-06T20:44:20.990231+00:00 [queued]>
[2022-09-06 20:44:24,920] {taskinstance.py:1376} INFO - 
--------------------------------------------------------------------------------
[2022-09-06 20:44:24,921] {taskinstance.py:1377} INFO - Starting attempt 1 of 1
[2022-09-06 20:44:24,922] {taskinstance.py:1378} INFO - 
--------------------------------------------------------------------------------
[2022-09-06 20:44:24,940] {taskinstance.py:1397} INFO - Executing <Task(PostgresOperator): create_table> on 2022-09-06 20:44:20.990231+00:00
[2022-09-06 20:44:24,947] {standard_task_runner.py:52} INFO - Started process 10271 to run task
[2022-09-06 20:44:24,952] {standard_task_runner.py:79} INFO - Running: ['***', 'tasks', 'run', 'tables_name_1', 'create_table', 'manual__2022-09-06T20:44:20.990231+00:00', '--job-id', '3892', '--raw', '--subdir', 'DAGS_FOLDER/jobs_dag.py', '--cfg-path', '/tmp/tmpnup6vwbn', '--error-file', '/tmp/tmpcc_7661y']
[2022-09-06 20:44:24,953] {standard_task_runner.py:80} INFO - Job 3892: Subtask create_table
[2022-09-06 20:44:25,039] {task_command.py:371} INFO - Running <TaskInstance: tables_name_1.create_table manual__2022-09-06T20:44:20.990231+00:00 [running]> on host eba23da77ca5
[2022-09-06 20:44:25,134] {taskinstance.py:1591} INFO - Exporting the following env vars:
AIRFLOW_CTX_DAG_OWNER=***
AIRFLOW_CTX_DAG_ID=tables_name_1
AIRFLOW_CTX_TASK_ID=create_table
AIRFLOW_CTX_EXECUTION_DATE=2022-09-06T20:44:20.990231+00:00
AIRFLOW_CTX_TRY_NUMBER=1
AIRFLOW_CTX_DAG_RUN_ID=manual__2022-09-06T20:44:20.990231+00:00
[2022-09-06 20:44:25,147] {base.py:68} INFO - Using connection ID 'postgres_default' for task execution.
[2022-09-06 20:44:25,158] {dbapi.py:231} INFO - Running statement: -- create table
CREATE TABLE pg_catalog.pg_tables.my_table(custom_id integer NOT NULL, user_name VARCHAR (50) NOT NULL, timestamp TIMESTAMP NOT NULL);, parameters: None
[2022-09-06 20:44:25,160] {taskinstance.py:1909} ERROR - Task failed with exception
Traceback (most recent call last):
  File "/home/airflow/.local/lib/python3.7/site-packages/airflow/providers/postgres/operators/postgres.py", line 92, in execute
    self.hook.run(self.sql, self.autocommit, parameters=self.parameters)
  File "/home/airflow/.local/lib/python3.7/site-packages/airflow/hooks/dbapi.py", line 211, in run
    self._run_command(cur, sql_statement, parameters)
  File "/home/airflow/.local/lib/python3.7/site-packages/airflow/hooks/dbapi.py", line 235, in _run_command
    cur.execute(sql_statement)
psycopg2.errors.FeatureNotSupported: cross-database references are not implemented: "pg_catalog.pg_tables.my_table"
LINE 2: CREATE TABLE pg_catalog.pg_tables.my_table(custom_id integer...
                     ^

[2022-09-06 20:44:25,172] {taskinstance.py:1420} INFO - Marking task as FAILED. dag_id=tables_name_1, task_id=create_table, execution_date=20220906T204420, start_date=20220906T204424, end_date=20220906T204425
[2022-09-06 20:44:25,186] {standard_task_runner.py:97} ERROR - Failed to execute job 3892 for task create_table (cross-database references are not implemented: "pg_catalog.pg_tables.my_table"
LINE 2: CREATE TABLE pg_catalog.pg_tables.my_table(custom_id integer...
                     ^
; 10271)
[2022-09-06 20:44:25,205] {local_task_job.py:156} INFO - Task exited with return code 1
[2022-09-06 20:44:25,266] {local_task_job.py:273} INFO - 0 downstream tasks scheduled from follow-on schedule check
