[2022-08-26 16:33:46,077] {taskinstance.py:1179} INFO - Dependencies all met for <TaskInstance: trigger_sensor.waiting_for_run_file manual__2022-08-26T16:33:44.472962+00:00 [queued]>
[2022-08-26 16:33:46,092] {taskinstance.py:1179} INFO - Dependencies all met for <TaskInstance: trigger_sensor.waiting_for_run_file manual__2022-08-26T16:33:44.472962+00:00 [queued]>
[2022-08-26 16:33:46,093] {taskinstance.py:1376} INFO - 
--------------------------------------------------------------------------------
[2022-08-26 16:33:46,094] {taskinstance.py:1377} INFO - Starting attempt 1 of 1
[2022-08-26 16:33:46,095] {taskinstance.py:1378} INFO - 
--------------------------------------------------------------------------------
[2022-08-26 16:33:46,124] {taskinstance.py:1397} INFO - Executing <Task(FileSensor): waiting_for_run_file> on 2022-08-26 16:33:44.472962+00:00
[2022-08-26 16:33:46,136] {standard_task_runner.py:52} INFO - Started process 19090 to run task
[2022-08-26 16:33:46,142] {standard_task_runner.py:79} INFO - Running: ['***', 'tasks', 'run', 'trigger_sensor', 'waiting_for_run_file', 'manual__2022-08-26T16:33:44.472962+00:00', '--job-id', '3262', '--raw', '--subdir', 'DAGS_FOLDER/trigger_dag.py', '--cfg-path', '/tmp/tmp9sqjbnst', '--error-file', '/tmp/tmpic94z2uo']
[2022-08-26 16:33:46,144] {standard_task_runner.py:80} INFO - Job 3262: Subtask waiting_for_run_file
[2022-08-26 16:33:46,244] {task_command.py:371} INFO - Running <TaskInstance: trigger_sensor.waiting_for_run_file manual__2022-08-26T16:33:44.472962+00:00 [running]> on host 9d5d2a77e6ba
[2022-08-26 16:33:46,379] {taskinstance.py:1591} INFO - Exporting the following env vars:
AIRFLOW_CTX_DAG_OWNER=***
AIRFLOW_CTX_DAG_ID=trigger_sensor
AIRFLOW_CTX_TASK_ID=waiting_for_run_file
AIRFLOW_CTX_EXECUTION_DATE=2022-08-26T16:33:44.472962+00:00
AIRFLOW_CTX_TRY_NUMBER=1
AIRFLOW_CTX_DAG_RUN_ID=manual__2022-08-26T16:33:44.472962+00:00
[2022-08-26 16:33:46,440] {taskinstance.py:1909} ERROR - Task failed with exception
Traceback (most recent call last):
  File "/home/airflow/.local/lib/python3.7/site-packages/airflow/sensors/base.py", line 277, in execute
    poke_return = self.poke(context)
  File "/home/airflow/.local/lib/python3.7/site-packages/airflow/sensors/filesystem.py", line 55, in poke
    hook = FSHook(self.fs_conn_id)
  File "/home/airflow/.local/lib/python3.7/site-packages/airflow/hooks/filesystem.py", line 38, in __init__
    conn = self.get_connection(conn_id)
  File "/home/airflow/.local/lib/python3.7/site-packages/airflow/hooks/base.py", line 67, in get_connection
    conn = Connection.get_connection_from_secrets(conn_id)
  File "/home/airflow/.local/lib/python3.7/site-packages/airflow/models/connection.py", line 430, in get_connection_from_secrets
    raise AirflowNotFoundException(f"The conn_id `{conn_id}` isn't defined")
airflow.exceptions.AirflowNotFoundException: The conn_id `fs_default` isn't defined
[2022-08-26 16:33:46,453] {taskinstance.py:1420} INFO - Marking task as FAILED. dag_id=trigger_sensor, task_id=waiting_for_run_file, execution_date=20220826T163344, start_date=20220826T163346, end_date=20220826T163346
[2022-08-26 16:33:46,474] {standard_task_runner.py:97} ERROR - Failed to execute job 3262 for task waiting_for_run_file (The conn_id `fs_default` isn't defined; 19090)
[2022-08-26 16:33:46,520] {local_task_job.py:156} INFO - Task exited with return code 1
[2022-08-26 16:33:46,603] {local_task_job.py:273} INFO - 0 downstream tasks scheduled from follow-on schedule check
