[2022-08-17 14:39:13,362] {taskinstance.py:1179} INFO - Dependencies all met for <TaskInstance: my_dag.choose_best_model scheduled__2022-08-16T00:00:00+00:00 [queued]>
[2022-08-17 14:39:13,375] {taskinstance.py:1179} INFO - Dependencies all met for <TaskInstance: my_dag.choose_best_model scheduled__2022-08-16T00:00:00+00:00 [queued]>
[2022-08-17 14:39:13,376] {taskinstance.py:1376} INFO - 
--------------------------------------------------------------------------------
[2022-08-17 14:39:13,377] {taskinstance.py:1377} INFO - Starting attempt 1 of 1
[2022-08-17 14:39:13,377] {taskinstance.py:1378} INFO - 
--------------------------------------------------------------------------------
[2022-08-17 14:39:13,404] {taskinstance.py:1397} INFO - Executing <Task(BranchPythonOperator): choose_best_model> on 2022-08-16 00:00:00+00:00
[2022-08-17 14:39:13,427] {standard_task_runner.py:52} INFO - Started process 1810 to run task
[2022-08-17 14:39:13,432] {standard_task_runner.py:79} INFO - Running: ['***', 'tasks', 'run', 'my_dag', 'choose_best_model', 'scheduled__2022-08-16T00:00:00+00:00', '--job-id', '58', '--raw', '--subdir', 'DAGS_FOLDER/my_dag.py', '--cfg-path', '/tmp/tmpu6s9kv52', '--error-file', '/tmp/tmp_t2sew1f']
[2022-08-17 14:39:13,433] {standard_task_runner.py:80} INFO - Job 58: Subtask choose_best_model
[2022-08-17 14:39:13,538] {task_command.py:371} INFO - Running <TaskInstance: my_dag.choose_best_model scheduled__2022-08-16T00:00:00+00:00 [running]> on host 9d5d2a77e6ba
[2022-08-17 14:39:13,631] {taskinstance.py:1591} INFO - Exporting the following env vars:
AIRFLOW_CTX_DAG_OWNER=***
AIRFLOW_CTX_DAG_ID=my_dag
AIRFLOW_CTX_TASK_ID=choose_best_model
AIRFLOW_CTX_EXECUTION_DATE=2022-08-16T00:00:00+00:00
AIRFLOW_CTX_TRY_NUMBER=1
AIRFLOW_CTX_DAG_RUN_ID=scheduled__2022-08-16T00:00:00+00:00
[2022-08-17 14:39:13,645] {python.py:173} INFO - Done. Returned value was: innacurate
[2022-08-17 14:39:13,663] {taskinstance.py:1909} ERROR - Task failed with exception
Traceback (most recent call last):
  File "/home/airflow/.local/lib/python3.7/site-packages/airflow/operators/python.py", line 221, in execute
    f"Branch callable must return valid task_ids. Invalid tasks found: {invalid_task_ids}"
airflow.exceptions.AirflowException: Branch callable must return valid task_ids. Invalid tasks found: {'innacurate'}
[2022-08-17 14:39:13,669] {taskinstance.py:1420} INFO - Marking task as FAILED. dag_id=my_dag, task_id=choose_best_model, execution_date=20220816T000000, start_date=20220817T143913, end_date=20220817T143913
[2022-08-17 14:39:13,685] {standard_task_runner.py:97} ERROR - Failed to execute job 58 for task choose_best_model (Branch callable must return valid task_ids. Invalid tasks found: {'innacurate'}; 1810)
[2022-08-17 14:39:13,727] {local_task_job.py:156} INFO - Task exited with return code 1
[2022-08-17 14:39:13,790] {local_task_job.py:273} INFO - 0 downstream tasks scheduled from follow-on schedule check
