[2022-09-01 19:12:48,406] {taskinstance.py:1179} INFO - Dependencies all met for <TaskInstance: trigger_sensor.process_results.sensor_triggered_dag manual__2022-09-01T19:12:45.265000+00:00 [queued]>
[2022-09-01 19:12:48,419] {taskinstance.py:1179} INFO - Dependencies all met for <TaskInstance: trigger_sensor.process_results.sensor_triggered_dag manual__2022-09-01T19:12:45.265000+00:00 [queued]>
[2022-09-01 19:12:48,420] {taskinstance.py:1376} INFO - 
--------------------------------------------------------------------------------
[2022-09-01 19:12:48,421] {taskinstance.py:1377} INFO - Starting attempt 1 of 1
[2022-09-01 19:12:48,421] {taskinstance.py:1378} INFO - 
--------------------------------------------------------------------------------
[2022-09-01 19:12:48,438] {taskinstance.py:1397} INFO - Executing <Task(ExternalTaskSensor): process_results.sensor_triggered_dag> on 2022-09-01 19:12:45.265000+00:00
[2022-09-01 19:12:48,447] {standard_task_runner.py:52} INFO - Started process 89810 to run task
[2022-09-01 19:12:48,452] {standard_task_runner.py:79} INFO - Running: ['***', 'tasks', 'run', 'trigger_sensor', 'process_results.sensor_triggered_dag', 'manual__2022-09-01T19:12:45.265000+00:00', '--job-id', '3513', '--raw', '--subdir', 'DAGS_FOLDER/trigger_dag.py', '--cfg-path', '/tmp/tmpu_ek6uqn', '--error-file', '/tmp/tmpt4qsyhx5']
[2022-09-01 19:12:48,453] {standard_task_runner.py:80} INFO - Job 3513: Subtask process_results.sensor_triggered_dag
[2022-09-01 19:12:48,536] {task_command.py:371} INFO - Running <TaskInstance: trigger_sensor.process_results.sensor_triggered_dag manual__2022-09-01T19:12:45.265000+00:00 [running]> on host 9d5d2a77e6ba
[2022-09-01 19:12:48,625] {taskinstance.py:1591} INFO - Exporting the following env vars:
AIRFLOW_CTX_DAG_OWNER=***
AIRFLOW_CTX_DAG_ID=trigger_sensor
AIRFLOW_CTX_TASK_ID=process_results.sensor_triggered_dag
AIRFLOW_CTX_EXECUTION_DATE=2022-09-01T19:12:45.265000+00:00
AIRFLOW_CTX_TRY_NUMBER=1
AIRFLOW_CTX_DAG_RUN_ID=manual__2022-09-01T19:12:45.265000+00:00
[2022-09-01 19:12:48,628] {taskinstance.py:1909} ERROR - Task failed with exception
Traceback (most recent call last):
  File "/home/airflow/.local/lib/python3.7/site-packages/airflow/sensors/base.py", line 277, in execute
    poke_return = self.poke(context)
  File "/home/airflow/.local/lib/python3.7/site-packages/airflow/utils/session.py", line 71, in wrapper
    return func(*args, session=session, **kwargs)
  File "/home/airflow/.local/lib/python3.7/site-packages/airflow/sensors/external_task.py", line 177, in poke
    dttm = self._handle_execution_date_fn(context=context)
  File "/home/airflow/.local/lib/python3.7/site-packages/airflow/sensors/external_task.py", line 296, in _handle_execution_date_fn
    return kwargs_callable(logical_date, **kwargs)
  File "/home/airflow/.local/lib/python3.7/site-packages/airflow/utils/operator_helpers.py", line 208, in kwargs_func
    kwargs = determine_kwargs(func, args, kwargs)
  File "/home/airflow/.local/lib/python3.7/site-packages/airflow/utils/operator_helpers.py", line 196, in determine_kwargs
    return KeywordParameters.determine(func, args, kwargs).unpacking()
  File "/home/airflow/.local/lib/python3.7/site-packages/airflow/utils/operator_helpers.py", line 154, in determine
    signature = inspect.signature(func)
  File "/usr/local/lib/python3.7/inspect.py", line 3083, in signature
    return Signature.from_callable(obj, follow_wrapped=follow_wrapped)
  File "/usr/local/lib/python3.7/inspect.py", line 2833, in from_callable
    follow_wrapper_chains=follow_wrapped)
  File "/usr/local/lib/python3.7/inspect.py", line 2208, in _signature_from_callable
    raise TypeError('{!r} is not a callable object'.format(obj))
TypeError: datetime.datetime(2018, 10, 11, 0, 0) is not a callable object
[2022-09-01 19:12:48,641] {taskinstance.py:1420} INFO - Marking task as FAILED. dag_id=trigger_sensor, task_id=process_results.sensor_triggered_dag, execution_date=20220901T191245, start_date=20220901T191248, end_date=20220901T191248
[2022-09-01 19:12:48,655] {standard_task_runner.py:97} ERROR - Failed to execute job 3513 for task process_results.sensor_triggered_dag (datetime.datetime(2018, 10, 11, 0, 0) is not a callable object; 89810)
[2022-09-01 19:12:48,710] {local_task_job.py:156} INFO - Task exited with return code 1
[2022-09-01 19:12:48,773] {local_task_job.py:273} INFO - 0 downstream tasks scheduled from follow-on schedule check
