[2022-09-06 17:13:15,810] {taskinstance.py:1179} INFO - Dependencies all met for <TaskInstance: tables_name_1.create_table manual__2022-09-06T17:13:11.527275+00:00 [queued]>
[2022-09-06 17:13:15,823] {taskinstance.py:1179} INFO - Dependencies all met for <TaskInstance: tables_name_1.create_table manual__2022-09-06T17:13:11.527275+00:00 [queued]>
[2022-09-06 17:13:15,824] {taskinstance.py:1376} INFO - 
--------------------------------------------------------------------------------
[2022-09-06 17:13:15,825] {taskinstance.py:1377} INFO - Starting attempt 1 of 1
[2022-09-06 17:13:15,826] {taskinstance.py:1378} INFO - 
--------------------------------------------------------------------------------
[2022-09-06 17:13:15,842] {taskinstance.py:1397} INFO - Executing <Task(PostgresOperator): create_table> on 2022-09-06 17:13:11.527275+00:00
[2022-09-06 17:13:15,849] {standard_task_runner.py:52} INFO - Started process 8967 to run task
[2022-09-06 17:13:15,853] {standard_task_runner.py:79} INFO - Running: ['***', 'tasks', 'run', 'tables_name_1', 'create_table', 'manual__2022-09-06T17:13:11.527275+00:00', '--job-id', '3883', '--raw', '--subdir', 'DAGS_FOLDER/jobs_dag.py', '--cfg-path', '/tmp/tmp86nnuu7n', '--error-file', '/tmp/tmpvpradnjc']
[2022-09-06 17:13:15,854] {standard_task_runner.py:80} INFO - Job 3883: Subtask create_table
[2022-09-06 17:13:15,941] {task_command.py:371} INFO - Running <TaskInstance: tables_name_1.create_table manual__2022-09-06T17:13:11.527275+00:00 [running]> on host eba23da77ca5
[2022-09-06 17:13:16,032] {taskinstance.py:1591} INFO - Exporting the following env vars:
AIRFLOW_CTX_DAG_OWNER=***
AIRFLOW_CTX_DAG_ID=tables_name_1
AIRFLOW_CTX_TASK_ID=create_table
AIRFLOW_CTX_EXECUTION_DATE=2022-09-06T17:13:11.527275+00:00
AIRFLOW_CTX_TRY_NUMBER=1
AIRFLOW_CTX_DAG_RUN_ID=manual__2022-09-06T17:13:11.527275+00:00
[2022-09-06 17:13:16,044] {base.py:68} INFO - Using connection ID 'postgres_default' for task execution.
[2022-09-06 17:13:16,053] {dbapi.py:231} INFO - Running statement: CREATE TABLE my_table(custom_id integer NOT NULL, user_name VARCHAR (50) NOT NULL, timestamp TIMESTAMP NOT NULL);, parameters: None
[2022-09-06 17:13:16,055] {taskinstance.py:1909} ERROR - Task failed with exception
Traceback (most recent call last):
  File "/home/airflow/.local/lib/python3.7/site-packages/airflow/providers/postgres/operators/postgres.py", line 92, in execute
    self.hook.run(self.sql, self.autocommit, parameters=self.parameters)
  File "/home/airflow/.local/lib/python3.7/site-packages/airflow/hooks/dbapi.py", line 211, in run
    self._run_command(cur, sql_statement, parameters)
  File "/home/airflow/.local/lib/python3.7/site-packages/airflow/hooks/dbapi.py", line 235, in _run_command
    cur.execute(sql_statement)
psycopg2.errors.DuplicateTable: relation "my_table" already exists

[2022-09-06 17:13:16,066] {taskinstance.py:1420} INFO - Marking task as FAILED. dag_id=tables_name_1, task_id=create_table, execution_date=20220906T171311, start_date=20220906T171315, end_date=20220906T171316
[2022-09-06 17:13:16,078] {standard_task_runner.py:97} ERROR - Failed to execute job 3883 for task create_table (relation "my_table" already exists
; 8967)
[2022-09-06 17:13:16,106] {local_task_job.py:156} INFO - Task exited with return code 1
[2022-09-06 17:13:16,161] {local_task_job.py:273} INFO - 0 downstream tasks scheduled from follow-on schedule check
