[2022-09-06 20:56:50,668] {taskinstance.py:1179} INFO - Dependencies all met for <TaskInstance: tables_name_1.check_table_exist manual__2022-09-06T20:56:47.540771+00:00 [queued]>
[2022-09-06 20:56:50,684] {taskinstance.py:1179} INFO - Dependencies all met for <TaskInstance: tables_name_1.check_table_exist manual__2022-09-06T20:56:47.540771+00:00 [queued]>
[2022-09-06 20:56:50,685] {taskinstance.py:1376} INFO - 
--------------------------------------------------------------------------------
[2022-09-06 20:56:50,686] {taskinstance.py:1377} INFO - Starting attempt 1 of 1
[2022-09-06 20:56:50,687] {taskinstance.py:1378} INFO - 
--------------------------------------------------------------------------------
[2022-09-06 20:56:50,708] {taskinstance.py:1397} INFO - Executing <Task(BranchPythonOperator): check_table_exist> on 2022-09-06 20:56:47.540771+00:00
[2022-09-06 20:56:50,715] {standard_task_runner.py:52} INFO - Started process 10852 to run task
[2022-09-06 20:56:50,724] {standard_task_runner.py:79} INFO - Running: ['***', 'tasks', 'run', 'tables_name_1', 'check_table_exist', 'manual__2022-09-06T20:56:47.540771+00:00', '--job-id', '3897', '--raw', '--subdir', 'DAGS_FOLDER/jobs_dag.py', '--cfg-path', '/tmp/tmpjmrbbyrw', '--error-file', '/tmp/tmp5g10mkah']
[2022-09-06 20:56:50,725] {standard_task_runner.py:80} INFO - Job 3897: Subtask check_table_exist
[2022-09-06 20:56:50,857] {task_command.py:371} INFO - Running <TaskInstance: tables_name_1.check_table_exist manual__2022-09-06T20:56:47.540771+00:00 [running]> on host eba23da77ca5
[2022-09-06 20:56:50,969] {taskinstance.py:1591} INFO - Exporting the following env vars:
AIRFLOW_CTX_DAG_OWNER=***
AIRFLOW_CTX_DAG_ID=tables_name_1
AIRFLOW_CTX_TASK_ID=check_table_exist
AIRFLOW_CTX_EXECUTION_DATE=2022-09-06T20:56:47.540771+00:00
AIRFLOW_CTX_TRY_NUMBER=1
AIRFLOW_CTX_DAG_RUN_ID=manual__2022-09-06T20:56:47.540771+00:00
[2022-09-06 20:56:50,984] {base.py:68} INFO - Using connection ID 'postgres_default' for task execution.
[2022-09-06 20:56:51,000] {jobs_dag.py:41} INFO - THIS IS FIRST QUERY:
[2022-09-06 20:56:51,002] {jobs_dag.py:42} INFO - [('pg_statistic',), ('pg_type',), ('dag_runs',), ('pg_foreign_table',), ('pg_authid',), ('my_table',), ('pg_statistic_ext_data',), ('pg_user_mapping',), ('pg_subscription',), ('pg_attribute',), ('pg_proc',), ('pg_class',), ('pg_attrdef',), ('pg_constraint',), ('pg_inherits',), ('pg_index',), ('pg_operator',), ('pg_opfamily',), ('pg_opclass',), ('pg_am',), ('pg_amop',), ('pg_amproc',), ('pg_language',), ('pg_largeobject_metadata',), ('pg_aggregate',), ('pg_statistic_ext',), ('pg_rewrite',), ('pg_trigger',), ('pg_event_trigger',), ('pg_description',), ('pg_cast',), ('pg_enum',), ('pg_namespace',), ('pg_conversion',), ('pg_depend',), ('pg_database',), ('pg_db_role_setting',), ('pg_tablespace',), ('pg_auth_members',), ('pg_shdepend',), ('pg_shdescription',), ('pg_ts_config',), ('pg_ts_config_map',), ('pg_ts_dict',), ('pg_ts_parser',), ('pg_ts_template',), ('pg_extension',), ('pg_foreign_data_wrapper',), ('pg_foreign_server',), ('pg_policy',), ('pg_replication_origin',), ('pg_default_acl',), ('pg_init_privs',), ('pg_seclabel',), ('pg_shseclabel',), ('pg_collation',), ('pg_partitioned_table',), ('pg_range',), ('pg_transform',), ('pg_sequence',), ('pg_publication',), ('pg_publication_rel',), ('pg_subscription_rel',), ('pg_largeobject',), ('sql_parts',), ('sql_implementation_info',), ('sql_features',), ('sql_sizing',)]
[2022-09-06 20:56:51,003] {taskinstance.py:1909} ERROR - Task failed with exception
Traceback (most recent call last):
  File "/home/airflow/.local/lib/python3.7/site-packages/airflow/operators/python.py", line 207, in execute
    branch = super().execute(context)
  File "/home/airflow/.local/lib/python3.7/site-packages/airflow/operators/python.py", line 171, in execute
    return_value = self.execute_callable()
  File "/home/airflow/.local/lib/python3.7/site-packages/airflow/operators/python.py", line 189, in execute_callable
    return self.python_callable(*self.op_args, **self.op_kwargs)
  File "/opt/airflow/dags/jobs_dag.py", line 51, in check_table_exist
    query = hook.get_first(sql=sql_to_check_table_exist.format(schema, table_name))
UnboundLocalError: local variable 'schema' referenced before assignment
[2022-09-06 20:56:51,020] {taskinstance.py:1420} INFO - Marking task as FAILED. dag_id=tables_name_1, task_id=check_table_exist, execution_date=20220906T205647, start_date=20220906T205650, end_date=20220906T205651
[2022-09-06 20:56:51,043] {standard_task_runner.py:97} ERROR - Failed to execute job 3897 for task check_table_exist (local variable 'schema' referenced before assignment; 10852)
[2022-09-06 20:56:51,099] {local_task_job.py:156} INFO - Task exited with return code 1
[2022-09-06 20:56:51,184] {local_task_job.py:273} INFO - 0 downstream tasks scheduled from follow-on schedule check
