[2022-09-05 19:57:27,824] {taskinstance.py:1179} INFO - Dependencies all met for <TaskInstance: my_dag_postgres2.insert_into_table manual__2022-09-05T19:57:25.480846+00:00 [queued]>
[2022-09-05 19:57:27,835] {taskinstance.py:1179} INFO - Dependencies all met for <TaskInstance: my_dag_postgres2.insert_into_table manual__2022-09-05T19:57:25.480846+00:00 [queued]>
[2022-09-05 19:57:27,836] {taskinstance.py:1376} INFO - 
--------------------------------------------------------------------------------
[2022-09-05 19:57:27,837] {taskinstance.py:1377} INFO - Starting attempt 1 of 1
[2022-09-05 19:57:27,837] {taskinstance.py:1378} INFO - 
--------------------------------------------------------------------------------
[2022-09-05 19:57:27,854] {taskinstance.py:1397} INFO - Executing <Task(PostgresOperator): insert_into_table> on 2022-09-05 19:57:25.480846+00:00
[2022-09-05 19:57:27,861] {standard_task_runner.py:52} INFO - Started process 2310 to run task
[2022-09-05 19:57:27,865] {standard_task_runner.py:79} INFO - Running: ['***', 'tasks', 'run', 'my_dag_postgres2', 'insert_into_table', 'manual__2022-09-05T19:57:25.480846+00:00', '--job-id', '3827', '--raw', '--subdir', 'DAGS_FOLDER/dag_with_postgres.py', '--cfg-path', '/tmp/tmp486uroai', '--error-file', '/tmp/tmp5gg88u9l']
[2022-09-05 19:57:27,866] {standard_task_runner.py:80} INFO - Job 3827: Subtask insert_into_table
[2022-09-05 19:57:27,980] {task_command.py:371} INFO - Running <TaskInstance: my_dag_postgres2.insert_into_table manual__2022-09-05T19:57:25.480846+00:00 [running]> on host eba23da77ca5
[2022-09-05 19:57:28,079] {taskinstance.py:1591} INFO - Exporting the following env vars:
AIRFLOW_CTX_DAG_OWNER=***
AIRFLOW_CTX_DAG_ID=my_dag_postgres2
AIRFLOW_CTX_TASK_ID=insert_into_table
AIRFLOW_CTX_EXECUTION_DATE=2022-09-05T19:57:25.480846+00:00
AIRFLOW_CTX_TRY_NUMBER=1
AIRFLOW_CTX_DAG_RUN_ID=manual__2022-09-05T19:57:25.480846+00:00
[2022-09-05 19:57:28,095] {base.py:68} INFO - Using connection ID 'postgres_localhost' for task execution.
[2022-09-05 19:57:28,105] {dbapi.py:231} INFO - Running statement: 
            insert into dag_runs (dt, dag_id) values ('2022-09-05', 'my_dag_postgres2')
            , parameters: None
[2022-09-05 19:57:28,108] {taskinstance.py:1909} ERROR - Task failed with exception
Traceback (most recent call last):
  File "/home/airflow/.local/lib/python3.7/site-packages/airflow/providers/postgres/operators/postgres.py", line 92, in execute
    self.hook.run(self.sql, self.autocommit, parameters=self.parameters)
  File "/home/airflow/.local/lib/python3.7/site-packages/airflow/hooks/dbapi.py", line 211, in run
    self._run_command(cur, sql_statement, parameters)
  File "/home/airflow/.local/lib/python3.7/site-packages/airflow/hooks/dbapi.py", line 235, in _run_command
    cur.execute(sql_statement)
psycopg2.errors.UniqueViolation: duplicate key value violates unique constraint "dag_runs_pkey"
DETAIL:  Key (dt, dag_id)=(2022-09-05, my_dag_postgres2) already exists.

[2022-09-05 19:57:28,121] {taskinstance.py:1420} INFO - Marking task as FAILED. dag_id=my_dag_postgres2, task_id=insert_into_table, execution_date=20220905T195725, start_date=20220905T195727, end_date=20220905T195728
[2022-09-05 19:57:28,133] {standard_task_runner.py:97} ERROR - Failed to execute job 3827 for task insert_into_table (duplicate key value violates unique constraint "dag_runs_pkey"
DETAIL:  Key (dt, dag_id)=(2022-09-05, my_dag_postgres2) already exists.
; 2310)
[2022-09-05 19:57:28,159] {local_task_job.py:156} INFO - Task exited with return code 1
[2022-09-05 19:57:28,201] {local_task_job.py:273} INFO - 0 downstream tasks scheduled from follow-on schedule check
